Workbook

Sheet Summary
A1: NVIDIA Corporation (NASDAQ: NVDA) - DCF Valuation Summary
A2: Valuation date 13-Oct-2026 | $ in millions except per share | Prepared from NVIDIA FY2026 Form 10-K data and Q2 FY2027 results (26-Aug-2026)
A4: Valuation snapshot
A5: Active scenario | B5: =Assumptions!B4 -> Base
A6: Current share price (12-Oct-2026 close) | B6: =Assumptions!B9 -> 226.32
A7: Intrinsic value - perpetuity growth | B7: =DCF!B51 -> 182.81152
A8: Intrinsic value - exit multiple | B8: =DCF!C51 -> 231.14976
A9: Intrinsic value - blended (live scenario) | B9: =DCF!D51 -> 206.98064
A10: Upside / (downside) vs price | B10: =DCF!D53 -> -0.085451407
A11: Recommendation (live scenario) | B11: =DCF!D54 -> HOLD
A12: Probability-weighted value (Bear/Base/Bull) | B12: =Scenarios!D8 -> 201.78653
A13: Upside / (downside), probability-weighted | B13: =Scenarios!E8 -> -0.1084017
A14: Model integrity | B14: =Checks!B16 -> ALL CHECKS PASS
A16: Scenario valuation | B16: Value/share | C16: Upside | D16: Probability | E16: FY36E revenue ($bn)
A17: Bear | B17: =Scenarios!D5 -> 71.803273 | C17: =Scenarios!E5 -> -0.68273563 | D17: =Scenarios!F5 -> 0.25 | E17: =Scenarios!B33/1000 -> 591.29432
A18: Base | B18: =Scenarios!D6 -> 206.98064 | C18: =Scenarios!E6 -> -0.085451407 | D18: =Scenarios!F6 -> 0.5 | E18: =Scenarios!B55/1000 -> 1356.4374
A19: Bull | B19: =Scenarios!D7 -> 321.38156 | C19: =Scenarios!E7 -> 0.42003164 | D19: =Scenarios!F7 -> 0.25 | E19: =Scenarios!B77/1000 -> 1781.9004
A20: Market price | B20: =Assumptions!B9 -> 226.32
A22: Key assumptions (live scenario)
A23: WACC | B23: =DCF!B14 -> 0.11852934
A24: Cost of equity (CAPM) | B24: =WACC!B7 -> 0.119
A25: Terminal growth | B25: =DCF!B16 -> 0.035
A26: Exit EV/EBITDA multiple | B26: =DCF!B18 -> 14
A27: RONIC | B27: =DCF!B17 -> 0.3
A28: FY2027E revenue ($mm) | B28: =Forecast!E7 -> 403804.06
A29: FY2030E revenue ($mm) | B29: =Forecast!H7 -> 821943.16
A30: FY2036E revenue ($mm) | B30: =Forecast!N7 -> 1356437.4
A31: FY2036E operating margin | B31: =Forecast!N8 -> 0.47
A32: Terminal value % of EV (perp. growth) | B32: =DCF!B30 -> 0.48644656
A33: Market-implied FY28-36 revenue CAGR | B33: =ReverseDCF!B25 -> 0.19716499
A34: Live-scenario FY28-36 revenue CAGR | B34: =ReverseDCF!B4 -> 0.14411557
A36: Investment view (analyst judgment - update if inputs change)
A37: Thesis: NVIDIA is the compute backbone of the AI build-out; revenue reached $215.9bn in FY2026 (+65%) and H1 FY2027 revenue was $177.8bn, with Q3 guided to $108bn. Data Center is ~93% of revenue.
A38: The market price embeds sustained hyper-growth followed by a long plateau of very high margins; the Reverse DCF tab shows the revenue CAGR and terminal margin the price requires.
A39: Valuation is dominated by terminal assumptions and the discount rate (beta 1.6 vs 2.2 moves WACC by ~3 pts); read Sensitivity before the headline number.
A40: Key risks: AI-capex digestion, customer concentration and circular financing of AI labs, custom silicon (TPU, Trainium, MTIA), China export controls, gross-margin normalisation, supply constraints (HBM, CoWoS).
A41: Catalysts: Vera Rubin ramp, sovereign AI, agentic/inference demand, $99bn remaining buyback authority, Q3 FY2027 results (late Nov 2026).

Sheet Assumptions
A1: NVIDIA (NVDA) DCF - Assumptions
A2: $ in millions unless stated. Blue = hard-coded input, black = formula, green = link to another sheet, yellow fill = key assumption.
A3: Scenario selector (1 = Bear, 2 = Base, 3 = Bull) | B3: 2 | C3: Change this one cell to flip the whole model (Forecast, DCF, Sensitivity, Summary).
A4: Active scenario | B4: =CHOOSE(B3,"Bear","Base","Bull") -> Base
A6: Market & valuation inputs
A7: Valuation date | B7: 46308 | C7: Date of analysis.
A8: FY2027 fiscal year-end | B8: 46418 | C8: NVIDIA FY ends last Sunday of January; FY2027 ends 31-Jan-2027.
A9: Share price (close, 12-Oct-2026) | B9: 226.32 | C9: Source: Google Finance / Motley Fool quote pages, close 12-Oct-2026.
A10: Diluted shares (mm) | B10: 24285 | C10: Q2 FY2027 diluted weighted-average shares, NVIDIA 8-K 26-Aug-2026.
A11: Risk-free rate (10Y UST) | B11: 0.047 | C11: Approx.: 10Y UST was 4.68% on 30-Jul-2026 (FRED via therighttrader.com). Refresh before publishing.
A12: Equity risk premium | B12: 0.045 | C12: Analyst assumption (typical range 4.0-5.5%).
A13: Equity beta | B13: 1.6 | C13: 5Y beta: 1.60 (TradingView) vs 2.22 (Google Finance), 12-Oct-2026. Lower end used; see WACC sheet.
A14: Pre-tax cost of debt | B14: 0.05 | C14: Analyst assumption; NVIDIA raised ~$25bn of debt in H1 FY2027 (Q2 FY27 cash flow statement).
A15: Tax rate for WACC | B15: 0.18 | C15: Mid-point of FY2027 guided tax rate 16-18% plus modest drift.
A16: Haircut factor on marketable equity securities | B16: 1 | C16: 1.0 = count at 100% of 26-Jul-2026 carrying value.
A17: Haircut factor on non-marketable securities | B17: 0.75 | C17: Judgment: strategic stakes (AI labs, partners) carried at cost/fair-value marks; 75% recognised.
A18: Weight on perpetuity-growth method in blended value | B18: 0.5 | C18: Remainder on exit-multiple method.
... A21: Probability - Bull | B21: 0.25 | C21: Analyst judgment.
A22: Operating NWC % of revenue (FY24-FY26 average) | B22: =AVERAGE(Historicals!B64:D64) -> 0.14655103 | C22: NWC = receivables + inventories + prepaid - payables - accrued liabilities. Stable at ~14.5-14.8% of revenue FY24-FY26.
A23: Buy/Sell threshold (+/- upside vs price) | B23: 0.15 | C23: BUY if blended upside > threshold, SELL if < -threshold, else HOLD.
A24: Q3 FY2027 revenue guidance (mid-point) | B24: 108000 | C24: NVIDIA Q2 FY27 outlook: $108.0bn +/-2%. Used in Checks.
A26: Scenario drivers
A27: Revenue growth (y/y) | E27: FY2027E | F27: FY2028E | G27: FY2029E | H27: FY2030E | I27: FY2031E | J27: FY2032E | K27: FY2033E | L27: FY2034E | M27: FY2035E | N27: FY2036E
A28: Bear | E28: 0.8 | F28: 0.15 | G28: 0.05 | H28: 0.02 | I28: 0.03 | J28: 0.04 | K28: 0.04 | L28: 0.04 | M28: 0.035 | N28: 0.03
A29: Base | E29: 0.87 | F29: 0.38 | G29: 0.25 | H29: 0.18 | I29: 0.14 | J29: 0.11 | K29: 0.09 | L29: 0.075 | M29: 0.06 | N29: 0.05
A30: Bull | E30: 0.92 | F30: 0.5 | G30: 0.32 | H30: 0.23 | I30: 0.17 | J30: 0.13 | K30: 0.1 | L30: 0.08 | M30: 0.065 | N30: 0.055
A31: Live (selected) | E31: =CHOOSE($B$3,E28,E29,E30) -> 0.87 | F31: =CHOOSE($B$3,F28,F29,F30) -> 0.38 | G31: =CHOOSE($B$3,G28,G29,G30) -> 0.25 | H31: =CHOOSE($B$3,H28,H29,H30) -> 0.18 | I31: =CHOOSE($B$3,I28,I29,I30) -> 0.14 | J31: =CHOOSE($B$3,J28,J29,J30) -> 0.11 | K31: =CHOOSE($B$3,K28,K29,K30) -> 0.09 | L31: =CHOOSE($B$3,L28,L29,L30) -> 0.075 | ... N31: =CHOOSE($B$3,N28,N29,N30) -> 0.05
A32: FY27 anchored to guidance: H1 FY27A revenue $177.8bn + Q3 guide $108bn; Base FY27E growth of 87% implies Q4 of ~$118bn. Later years fade toward GDP-like growth.
A34: Operating margin (GAAP EBIT / revenue) | E34: FY2027E | F34: FY2028E | G34: FY2029E | H34: FY2030E | I34: FY2031E | J34: FY2032E | K34: FY2033E | L34: FY2034E | M34: FY2035E | N34: FY2036E
A35: Bear | E35: 0.64 | F35: 0.58 | G35: 0.52 | H35: 0.46 | I35: 0.42 | J35: 0.39 | K35: 0.37 | L35: 0.35 | M35: 0.34 | N35: 0.33
A36: Base | E36: 0.65 | F36: 0.64 | G36: 0.62 | H36: 0.6 | I36: 0.58 | J36: 0.55 | K36: 0.53 | L36: 0.51 | M36: 0.49 | N36: 0.47
A37: Bull | E37: 0.66 | F37: 0.66 | G37: 0.65 | H37: 0.64 | I37: 0.62 | J37: 0.6 | K37: 0.58 | L37: 0.56 | M37: 0.54 | N37: 0.52
A38: Live (selected) | E38: =CHOOSE($B$3,E35,E36,E37) -> 0.65 | F38: =CHOOSE($B$3,F35,F36,F37) -> 0.64 | G38: =CHOOSE($B$3,G35,G36,G37) -> 0.62 | H38: =CHOOSE($B$3,H35,H36,H37) -> 0.6 | I38: =CHOOSE($B$3,I35,I36,I37) -> 0.58 | J38: =CHOOSE($B$3,J35,J36,J37) -> 0.55 | K38: =CHOOSE($B$3,K35,K36,K37) -> 0.53 | L38: =CHOOSE($B$3,L35,L36,L37) -> 0.51 | ... N38: =CHOOSE($B$3,N35,N36,N37) -> 0.47
A39: GAAP margin (stock-based comp treated as a real cost). FY26A 60.4%, H1 FY27A 65.9%; Q3 guide (74% GM, $9.2bn opex) implies ~65%. Fade reflects competition, custom ASICs, mix and customer pricing power.
A41: Common operating drivers (all scenarios) | E41: FY2027E | F41: FY2028E | G41: FY2029E | H41: FY2030E | I41: FY2031E | J41: FY2032E | K41: FY2033E | L41: FY2034E | M41: FY2035E | N41: FY2036E
A42: Tax rate on EBIT | E42: 0.17 | F42: 0.18 | G42: 0.18 | H42: 0.18 | I42: 0.18 | J42: 0.19 | K42: 0.19 | L42: 0.19 | M42: 0.19 | N42: 0.19
A43: D&A % of revenue | E43: 0.012 | F43: 0.012 | G43: 0.013 | H43: 0.014 | I43: 0.015 | J43: 0.016 | K43: 0.017 | L43: 0.018 | M43: 0.019 | N43: 0.02
A44: Capex % of revenue | E44: 0.025 | F44: 0.026 | G44: 0.026 | H44: 0.026 | I44: 0.026 | J44: 0.025 | K44: 0.025 | L44: 0.024 | M44: 0.024 | N44: 0.024
A45: FY27 tax guided 16-18%. FY26A D&A 1.3% and capex 2.8% of revenue; H1 FY27A 1.2% and 2.5%. Capex/D&A converge toward ~1.2x by FY36.
A47: Terminal assumptions
...

Sheet Historicals
A1: NVIDIA historical financials (US GAAP, $ in millions)
A2: FY ends last Sunday of January. Sources on Sources tab. H1 FY2027A = six months ended 26-Jul-2026; balance sheet column E = 26-Jul-2026.
A4: Income statement | B4: FY2024A | C4: FY2025A | D4: FY2026A | E4: H1 FY2027A
A6: Revenue | B6: 60922 | C6: 130497 | D6: 215938 | E6: 177837
A7: Cost of revenue | B7: 16621 | C7: 32639 | D7: 62475 | E7: 44538
A8: Gross profit | B8: =B6-B7 -> 44301 | C8: =C6-C7 -> 97858 | D8: =D6-D7 -> 153463 | E8: =E6-E7 -> 133299
A9: Research and development | B9: 8675 | C9: 12914 | D9: 18497 | E9: 13375
A10: Sales, general and administrative | B10: 2654 | C10: 3491 | D10: 4579 | E10: 2654
A11: Total operating expenses | B11: =B9+B10 -> 11329 | C11: =C9+C10 -> 16405 | D11: =D9+D10 -> 23076 | E11: =E9+E10 -> 16029
A12: Operating income (EBIT) | B12: =B8-B11 -> 32972 | C12: =C8-C11 -> 81453 | D12: =D8-D11 -> 130387 | E12: =E8-E11 -> 117270
A13: Other income, net (interest, gains & other) | B13: 846 | C13: 2573 | D13: 11063 | E13: 24140
A14: Income before income tax | B14: =B12+B13 -> 33818 | C14: =C12+C13 -> 84026 | D14: =D12+D13 -> 141450 | E14: =E12+E13 -> 141410
A15: Income tax expense | B15: 4058 | C15: 11146 | D15: 21383 | E15: 23400
A16: Net income | B16: =B14-B15 -> 29760 | C16: =C14-C15 -> 72880 | D16: =D14-D15 -> 120067 | E16: =E14-E15 -> 118010
A17: Diluted weighted-average shares (mm) | B17: 24940 | C17: 24804 | D17: 24514 | E17: 24338
A18: Diluted EPS ($) | B18: =B16/B17 -> 1.1932638 | C18: =C16/C17 -> 2.9382358 | D18: =D16/D17 -> 4.8978951 | E18: =E16/E17 -> 4.8487961
A20: Ratios
A21: Revenue growth (y/y) | B21: n/a | C21: =C6/B6-1 -> 1.1420341 | D21: =D6/C6-1 -> 0.65473536 | E21: n/a
A22: Gross margin | B22: =B8/B6 -> 0.72717573 | C22: =C8/C6 -> 0.74988697 | D22: =D8/D6 -> 0.71068084 | E22: =E8/E6 -> 0.74955718
A23: Operating margin | B23: =B12/B6 -> 0.54121664 | C23: =C12/C6 -> 0.62417527 | D23: =D12/D6 -> 0.60381684 | E23: =E12/E6 -> 0.65942408
A24: Effective tax rate | B24: =B15/B14 -> 0.11999527 | C24: =C15/C14 -> 0.13264942 | D24: =D15/D14 -> 0.15117002 | E24: =E15/E14 -> 0.16547627
A25: R&D % revenue | B25: =B9/B6 -> 0.14239519 | C25: =C9/C6 -> 0.098960129 | D25: =D9/D6 -> 0.085658847 | E25: =E9/E6 -> 0.075209321
A26: SG&A % revenue | B26: =B10/B6 -> 0.043563901 | C26: =C10/C6 -> 0.026751573 | D26: =D10/D6 -> 0.021205161 | E26: =E10/E6 -> 0.014923779
A28: Cash flow items
A29: Depreciation & amortization | B29: 1508 | C29: 1864 | D29: 2843 | E29: 2124
A30: Stock-based compensation | B30: 3549 | C30: 4737 | D30: 6386 | E30: 3954
A31: Capex (purchases of PP&E and intangibles) | B31: 1069 | C31: 3236 | D31: 6042 | E31: 4434
A32: Net cash from operating activities | B32: 28090 | C32: 64089 | D32: 102718 | E32: 74421
A33: Free cash flow (OCF - capex) | B33: =B32-B31 -> 27021 | C33: =C32-C31 -> 60853 | D33: =D32-D31 -> 96676 | E33: =E32-E31 -> 69987
A34: D&A % revenue | B34: =B29/B6 -> 0.024752963 | C34: =C29/C6 -> 0.014283853 | D34: =D29/D6 -> 0.013165816 | E34: =E29/E6 -> 0.011943521
A35: Capex % revenue | B35: =B31/B6 -> 0.017547027 | C35: =C31/C6 -> 0.024797505 | D35: =D31/D6 -> 0.027980254 | E35: =E31/E6 -> 0.024932944
A36: SBC % revenue | B36: =B30/B6 -> 0.058254818 | C36: =C30/C6 -> 0.036299685 | D36: =D30/D6 -> 0.029573303 | E36: =E30/E6 -> 0.022233843
A38: Balance sheet | B38: 28-Jan-24 | C38: 26-Jan-25 | D38: 25-Jan-26 | E38: 26-Jul-26
A39: Cash, equivalents & marketable debt securities | B39: 25984 | C39: 43210 | D39: 49670 | E39: 56586
A40: Marketable equity securities | B40: 0 | C40: 0 | D40: 12886 | E40: 42783
A41: Accounts receivable, net | B41: 9999 | C41: 23065 | D41: 38466 | E41: 63059
A42: Inventories | B42: 5282 | C42: 10080 | D42: 21403 | E42: 31575
A43: Prepaid expenses & other current assets | B43: 3080 | C43: 3771 | D43: 3180 | E43: 3409
A44: Total current assets | B44: =SUM(B39:B43) -> 44345 | C44: =SUM(C39:C43) -> 80126 | D44: =SUM(D39:D43) -> 125605 | E44: =SUM(E39:E43) -> 197412
A45: Property and equipment, net | B45: 3914 | C45: 6283 | D45: 10383 | E45: 14285
...

Sheet Forecast
A1: Forecast & free cash flow to firm (FCFF) - live scenario
A2: $ in millions. Scenario is selected on Assumptions!B3. FCFF = EBIT x (1 - t) + D&A - capex - change in NWC. SBC is NOT added back (treated as a real cost).
A3: Active scenario: | B3: =Assumptions!B4 -> Base
A4: Fiscal year (ends late January) | B4: FY2024A | C4: FY2025A | D4: FY2026A | E4: FY2027E | F4: FY2028E | G4: FY2029E | H4: FY2030E | I4: FY2031E | J4: FY2032E | K4: FY2033E | L4: FY2034E | M4: FY2035E | N4: FY2036E
A6: Revenue growth | B6: n/a | C6: =C7/B7-1 -> 1.1420341 | D6: =D7/C7-1 -> 0.65473536 | E6: =Assumptions!E31 -> 0.87 | F6: =Assumptions!F31 -> 0.38 | G6: =Assumptions!G31 -> 0.25 | H6: =Assumptions!H31 -> 0.18 | I6: =Assumptions!I31 -> 0.14 | J6: =Assumptions!J31 -> 0.11 | K6: =Assumptions!K31 -> 0.09 | L6: =Assumptions!L31 -> 0.075 | ... N6: =Assumptions!N31 -> 0.05
A7: Revenue | B7: =Historicals!B6 -> 60922 | C7: =Historicals!C6 -> 130497 | D7: =Historicals!D6 -> 215938 | E7: =D7*(1+E6) -> 403804.06 | F7: =E7*(1+F6) -> 557249.6 | G7: =F7*(1+G6) -> 696562 | H7: =G7*(1+H6) -> 821943.16 | I7: =H7*(1+I6) -> 937015.21 | J7: =I7*(1+J6) -> 1040086.9 | K7: =J7*(1+K6) -> 1133694.7 | L7: =K7*(1+L6) -> 1218721.8 | ... N7: =M7*(1+N6) -> 1356437.4
A8: Operating margin | B8: =Historicals!B23 -> 0.54121664 | C8: =Historicals!C23 -> 0.62417527 | D8: =Historicals!D23 -> 0.60381684 | E8: =Assumptions!E38 -> 0.65 | F8: =Assumptions!F38 -> 0.64 | G8: =Assumptions!G38 -> 0.62 | H8: =Assumptions!H38 -> 0.6 | I8: =Assumptions!I38 -> 0.58 | J8: =Assumptions!J38 -> 0.55 | K8: =Assumptions!K38 -> 0.53 | L8: =Assumptions!L38 -> 0.51 | ... N8: =Assumptions!N38 -> 0.47
A9: EBIT (GAAP operating income) | B9: =Historicals!B12 -> 32972 | C9: =Historicals!C12 -> 81453 | D9: =Historicals!D12 -> 130387 | E9: =E7*E8 -> 262472.64 | F9: =F7*F8 -> 356639.75 | G9: =G7*G8 -> 431868.44 | H9: =H7*H8 -> 493165.9 | I9: =I7*I8 -> 543468.82 | J9: =J7*J8 -> 572047.78 | K9: =K7*K8 -> 600858.19 | L9: =L7*L8 -> 621548.12 | ... N9: =N7*N8 -> 637525.56
A10: D&A % revenue | B10: =Historicals!B34 -> 0.024752963 | C10: =Historicals!C34 -> 0.014283853 | D10: =Historicals!D34 -> 0.013165816 | E10: =Assumptions!E43 -> 0.012 | F10: =Assumptions!F43 -> 0.012 | G10: =Assumptions!G43 -> 0.013 | H10: =Assumptions!H43 -> 0.014 | I10: =Assumptions!I43 -> 0.015 | J10: =Assumptions!J43 -> 0.016 | K10: =Assumptions!K43 -> 0.017 | L10: =Assumptions!L43 -> 0.018 | ... N10: =Assumptions!N43 -> 0.02
A11: D&A | B11: =Historicals!B29 -> 1508 | C11: =Historicals!C29 -> 1864 | D11: =Historicals!D29 -> 2843 | E11: =E7*E10 -> 4845.6487 | F11: =F7*F10 -> 6686.9952 | G11: =G7*G10 -> 9055.306 | H11: =H7*H10 -> 11507.204 | I11: =I7*I10 -> 14055.228 | J11: =J7*J10 -> 16641.39 | K11: =K7*K10 -> 19272.81 | L11: =L7*L10 -> 21936.992 | ... N11: =N7*N10 -> 27128.747
A12: EBITDA | B12: =B9+B11 -> 34480 | C12: =C9+C11 -> 83317 | D12: =D9+D11 -> 133230 | E12: =E9+E11 -> 267318.29 | F12: =F9+F11 -> 363326.74 | G12: =G9+G11 -> 440923.75 | H12: =H9+H11 -> 504673.1 | I12: =I9+I11 -> 557524.05 | ... N12: =N9+N11 -> 664654.31
A13: Tax rate | B13: =Historicals!B24 -> 0.11999527 | C13: =Historicals!C24 -> 0.13264942 | D13: =Historicals!D24 -> 0.15117002 | E13: =Assumptions!E42 -> 0.17 | F13: =Assumptions!F42 -> 0.18 | G13: =Assumptions!G42 -> 0.18 | H13: =Assumptions!H42 -> 0.18 | I13: =Assumptions!I42 -> 0.18 | J13: =Assumptions!J42 -> 0.19 | K13: =Assumptions!K42 -> 0.19 | L13: =Assumptions!L42 -> 0.19 | ... N13: =Assumptions!N42 -> 0.19
A14: Taxes on EBIT | B14: =B9*B13 -> 3956.484 | C14: =C9*C13 -> 10804.693 | D14: =D9*D13 -> 19710.606 | E14: =E9*E13 -> 44620.349 | F14: =F9*F13 -> 64195.154 | G14: =G9*G13 -> 77736.32 | H14: =H9*H13 -> 88769.862 | I14: =I9*I13 -> 97824.388 | ... N14: =N9*N13 -> 121129.86
A15: NOPAT | B15: =B9-B14 -> 29015.516 | C15: =C9-C14 -> 70648.307 | D15: =D9-D14 -> 110676.39 | E15: =E9-E14 -> 217852.29 | F15: =F9-F14 -> 292444.59 | G15: =G9-G14 -> 354132.12 | H15: =H9-H14 -> 404396.04 | I15: =I9-I14 -> 445644.43 | ... N15: =N9-N14 -> 516395.7
A16: Capex % revenue | B16: =Historicals!B35 -> 0.017547027 | C16: =Historicals!C35 -> 0.024797505 | D16: =Historicals!D35 -> 0.027980254 | E16: =Assumptions!E44 -> 0.025 | F16: =Assumptions!F44 -> 0.026 | G16: =Assumptions!G44 -> 0.026 | H16: =Assumptions!H44 -> 0.026 | I16: =Assumptions!I44 -> 0.026 | J16: =Assumptions!J44 -> 0.025 | K16: =Assumptions!K44 -> 0.025 | L16: =Assumptions!L44 -> 0.024 | ... N16: =Assumptions!N44 -> 0.024
A17: Capex | B17: =Historicals!B31 -> 1069 | C17: =Historicals!C31 -> 3236 | D17: =Historicals!D31 -> 6042 | E17: =E7*E16 -> 10095.102 | F17: =F7*F16 -> 14488.49 | G17: =G7*G16 -> 18110.612 | H17: =H7*H16 -> 21370.522 | I17: =I7*I16 -> 24362.395 | J17: =J7*J16 -> 26002.172 | K17: =K7*K16 -> 28342.367 | L17: =L7*L16 -> 29249.323 | ... N17: =N7*N16 -> 32554.497
A18: Operating NWC % revenue | B18: =Historicals!B64 -> 0.1474016 | C18: =Historicals!C64 -> 0.14459336 | D18: =Historicals!D64 -> 0.14765812 | E18: =Assumptions!$B$22 -> 0.14655103 | F18: =Assumptions!$B$22 -> 0.14655103 | G18: =Assumptions!$B$22 -> 0.14655103 | H18: =Assumptions!$B$22 -> 0.14655103 | I18: =Assumptions!$B$22 -> 0.14655103 | J18: =Assumptions!$B$22 -> 0.14655103 | K18: =Assumptions!$B$22 -> 0.14655103 | L18: =Assumptions!$B$22 -> 0.14655103 | ... N18: =Assumptions!$B$22 -> 0.14655103
A19: Operating NWC | B19: =Historicals!B63 -> 8980 | C19: =Historicals!C63 -> 18869 | D19: =Historicals!D63 -> 31885 | E19: =E7*E18 -> 59177.9 | F19: =F7*F18 -> 81665.502 | G19: =G7*G18 -> 102081.88 | H19: =H7*H18 -> 120456.62 | I19: =I7*I18 -> 137320.54 | J19: =J7*J18 -> 152425.8 | K19: =K7*K18 -> 166144.12 | L19: =L7*L18 -> 178604.93 | ... N19: =N7*N18 -> 198787.29
A20: Increase in NWC | B20: n/a | C20: =C19-B19 -> 9889 | D20: =D19-C19 -> 13016 | E20: =E19-D19 -> 27292.9 | F20: =F19-E19 -> 22487.602 | G20: =G19-F19 -> 20416.375 | H20: =H19-G19 -> 18374.738 | I20: =I19-H19 -> 16863.926 | J20: =J19-I19 -> 15105.26 | ... N20: =N19-M19 -> 9466.0614
A21: FCFF | B21: n/a | C21: =C15+C11-C17-C20 -> 59387.307 | D21: =D15+D11-D17-D20 -> 94461.394 | E21: =E15+E11-E17-E20 -> 185309.94 | F21: =F15+F11-F17-F20 -> 262155.5 | G21: =G15+G11-G17-G20 -> 324660.44 | H21: =H15+H11-H17-H20 -> 376157.98 | I21: =I15+I11-I17-I20 -> 418473.34 | J21: =J15+J11-J17-J20 -> 438892.66 | ... N21: =N15+N11-N17-N20 -> 501503.89
A22: FCFF margin | C22: =C21/C7 -> 0.45508561 | D22: =D21/D7 -> 0.43744683 | E22: =E21/E7 -> 0.45891054 | F22: =F21/F7 -> 0.47044537 | G22: =G21/G7 -> 0.46608979 | H22: =H21/H7 -> 0.45764476 | I22: =I21/I7 -> 0.44660251 | J22: =J21/J7 -> 0.42197693 | ... N22: =N21/N7 -> 0.36972138
A23: Reinvestment rate (net capex + dNWC) / NOPAT | C23: =(C17-C11+C20)/C15 -> 0.15939519 | D23: =(D17-D11+D20)/D15 -> 0.14650821 | E23: =(E17-E11+E20)/E15 -> 0.14937806 | F23: =(F17-F11+F20)/F15 -> 0.10357209 | G23: =(G17-G11+G20)/G15 -> 0.083222277 | H23: =(H17-H11+H20)/H15 -> 0.069827727 | I23: =(I17-I11+I20)/I15 -> 0.060970342 | J23: =(J17-J11+J20)/J15 -> 0.052801515 | ... N23: =(N17-N11+N20)/N15 -> 0.028837984
A25: Memo: revenue CAGR FY2027E-FY2036E | B25: =(N7/E7)^(1/9)-1 -> 0.14411557
A26: Memo: SBC as % of revenue, FY2026A (cost already inside EBIT) | B26: =Historicals!D36 -> 0.029573303

Sheet WACC
A1: Weighted average cost of capital
A2: Market-value weights. CAPM cost of equity.
A3: Cost of equity (CAPM)
A4: Risk-free rate | B4: =Assumptions!B11 -> 0.047
A5: Equity beta | B5: =Assumptions!B13 -> 1.6
A6: Equity risk premium | B6: =Assumptions!B12 -> 0.045
A7: Cost of equity = Rf + beta x ERP | B7: =B4+B5*B6 -> 0.119
A9: Cost of debt
A10: Pre-tax cost of debt | B10: =Assumptions!B14 -> 0.05
A11: Tax rate | B11: =Assumptions!B15 -> 0.18
A12: After-tax cost of debt | B12: =B10*(1-B11) -> 0.041
A14: Capital structure (market values, $mm)
A15: Equity market capitalisation (price x diluted shares) | B15: =Assumptions!B9*Assumptions!B10 -> 5496181.2
A16: Total debt (26-Jul-2026) | B16: =Historicals!E65 -> 33366
A17: Equity weight E/(D+E) | B17: =B15/(B15+B16) -> 0.99396587
A18: Debt weight D/(D+E) | B18: =B16/(B15+B16) -> 0.0060341288
A20: WACC | B20: =B17*B7+B18*B12 -> 0.11852934
A22: Beta cross-check (WACC at alternative betas)
A23: Beta 1.20 | B23: 1.2 | C23: =$B$17*($B$4+B23*$B$6)+$B$18*$B$12 -> 0.10063795
A24: Beta 1.40 | B24: 1.4 | C24: =$B$17*($B$4+B24*$B$6)+$B$18*$B$12 -> 0.10958365
A25: Beta 1.60 | B25: 1.6 | C25: =$B$17*($B$4+B25*$B$6)+$B$18*$B$12 -> 0.11852934
A26: Beta 1.80 | B26: 1.8 | C26: =$B$17*($B$4+B26*$B$6)+$B$18*$B$12 -> 0.12747503
A27: Beta 2.00 | B27: 2 | C27: =$B$17*($B$4+B27*$B$6)+$B$18*$B$12 -> 0.13642072
A28: Beta 2.22 | B28: 2.22 | C28: =$B$17*($B$4+B28*$B$6)+$B$18*$B$12 -> 0.14626099
A30: Observed 5Y betas on 12-Oct-2026: 1.60 (TradingView), 2.22 (Google Finance). A mega-cap with ~99% equity funding has WACC ~= cost of equity, so beta is the key discount-rate lever; see Sensitivity tab.

Sheet DCF
A1: Discounted cash flow valuation - live scenario
A2: $ in millions. Mid-year convention; stub period from valuation date to FY2027 year-end. Terminal value: value-driver perpetuity growth and exit multiple.
A3: Active scenario: | B3: =Assumptions!B4 -> Base
A4: Free cash flow to firm | E4: =Forecast!E4 -> FY2027E | F4: =Forecast!F4 -> FY2028E | G4: =Forecast!G4 -> FY2029E | H4: =Forecast!H4 -> FY2030E | I4: =Forecast!I4 -> FY2031E | J4: =Forecast!J4 -> FY2032E | K4: =Forecast!K4 -> FY2033E | L4: =Forecast!L4 -> FY2034E | ... N4: =Forecast!N4 -> FY2036E
A5: FCFF (full fiscal year) | E5: =Forecast!E21 -> 185309.94 | F5: =Forecast!F21 -> 262155.5 | G5: =Forecast!G21 -> 324660.44 | H5: =Forecast!H21 -> 376157.98 | I5: =Forecast!I21 -> 418473.34 | J5: =Forecast!J21 -> 438892.66 | K5: =Forecast!K21 -> 463907.25 | L5: =Forecast!L21 -> 483680.84 | ... N5: =Forecast!N21 -> 501503.89
A6: Fraction of year remaining after valuation date | E6: =$B$15 -> 0.30136986 | F6: 1 | G6: 1 | H6: 1 | I6: 1 | J6: 1 | K6: 1 | L6: 1 | M6: 1 | N6: 1
A7: FCFF included in valuation | E7: =E5*E6 -> 55846.831 | F7: =F5*F6 -> 262155.5 | G7: =G5*G6 -> 324660.44 | H7: =H5*H6 -> 376157.98 | I7: =I5*I6 -> 418473.34 | J7: =J5*J6 -> 438892.66 | K7: =K5*K6 -> 463907.25 | L7: =L5*L6 -> 483680.84 | ... N7: =N5*N6 -> 501503.89
A8: Discount period (years, mid-year convention) | E8: =$B$15/2 -> 0.15068493 | F8: =$B$15+0.5 -> 0.80136986 | G8: =F8+1 -> 1.8013699 | H8: =G8+1 -> 2.8013699 | I8: =H8+1 -> 3.8013699 | J8: =I8+1 -> 4.8013699 | K8: =J8+1 -> 5.8013699 | L8: =K8+1 -> 6.8013699 | M8: =L8+1 -> 7.8013699 | N8: =M8+1 -> 8.8013699
A9: Discount factor | E9: =1/(1+$B$14)^E8 -> 0.98326272 | F9: =1/(1+$B$14)^F8 -> 0.91414577 | G9: =1/(1+$B$14)^G8 -> 0.81727474 | H9: =1/(1+$B$14)^H8 -> 0.73066902 | I9: =1/(1+$B$14)^I8 -> 0.65324082 | J9: =1/(1+$B$14)^J8 -> 0.5840176 | K9: =1/(1+$B$14)^K8 -> 0.52212989 | L9: =1/(1+$B$14)^L8 -> 0.46680036 | ... N9: =1/(1+$B$14)^N8 -> 0.3731096
A10: PV of FCFF | E10: =E7*E9 -> 54912.106 | F10: =F7*F9 -> 239648.34 | G10: =G7*G9 -> 265336.78 | H10: =H7*H9 -> 274846.98 | I10: =I7*I9 -> 273363.87 | J10: =J7*J9 -> 256321.04 | K10: =K7*K9 -> 242219.84 | L10: =L7*L9 -> 225782.39 | ... N10: =N7*N9 -> 187115.92
A13: Valuation parameters
A14: WACC | B14: =WACC!B20 -> 0.11852934
A15: Stub fraction of FY2027 remaining ((FYE27 - valuation date) / 365) | B15: =(Assumptions!B8-Assumptions!B7)/365 -> 0.30136986
A16: Terminal growth rate (live) | B16: =Assumptions!E49 -> 0.035
A17: RONIC (live) | B17: =Assumptions!E50 -> 0.3
A18: Exit EV/EBITDA multiple (live) | B18: =Assumptions!E51 -> 14
A19: Sum of PV of explicit FCFF (stub FY27 to FY36) | B19: =SUM(E10:N10) -> 2226360.4
A21: Terminal value - perpetuity growth (value-driver)
A22: FY2036E revenue | B22: =Forecast!N7 -> 1356437.4
A23: FY2037 NOPAT = FY36 revenue x (1+g) x margin x (1-t) | B23: =B22*(1+B16)*Forecast!N8*(1-Forecast!N13) -> 534469.55
A24: Terminal reinvestment rate = g / RONIC | B24: =B16/B17 -> 0.11666667
A25: FY2037 FCFF = NOPAT x (1 - reinvestment) | B25: =B23*(1-B24) -> 472114.77
A26: Terminal value = FCFF / (WACC - g) | B26: =B25/(B14-B16) -> 5652083.3
A27: Discount period for TV (N - 0.5, mid-year basis) | B27: =B15+9-0.5 -> 8.8013699
A28: PV of terminal value | B28: =B26/(1+B14)^B27 -> 2108846.5
A29: Enterprise value | B29: =B19+B28 -> 4335206.9
A30: Terminal value % of EV | B30: =B28/B29 -> 0.48644656
A31: Implied EV/EBITDA at end of FY2036 (cross-check) | B31: =B26*(1+B14)^0.5/Forecast!N12 -> 8.993659
A33: Terminal value - exit multiple
A34: FY2036E EBITDA | B34: =Forecast!N12 -> 664654.31
A35: Exit multiple | B35: =B18 -> 14
A36: Terminal value | B36: =B34*B35 -> 9305160.3
A37: Discount period for TV (end of FY2036) | B37: =B15+9 -> 9.3013699
A38: PV of terminal value | B38: =B36/(1+B14)^B37 -> 3282740.8
A39: Enterprise value | B39: =B19+B38 -> 5509101.2
A40: Terminal value % of EV | B40: =B38/B39 -> 0.59587593
A41: Implied perpetuity growth (from FY36 FCFF) | B41: =(B36/(1+B14)^0.5*B14-Forecast!N21)/(B36/(1+B14)^0.5+Forecast!N21) -> 0.058211388
A43: Equity bridge ($mm, balance sheet 26-Jul-2026) | B43: Perpetuity growth | C43: Exit multiple | D43: Blended
A44: Enterprise value | B44: =B29 -> 4335206.9 | C44: =B39 -> 5509101.2 | D44: =Assumptions!B18*B44+(1-Assumptions!B18)*C44 -> 4922154
A45: Less: total debt | B45: =-Historicals!$E$65 -> -33366 | C45: =-Historicals!$E$65 -> -33366 | D45: =-Historicals!$E$65 -> -33366
...

Sheet Sensitivity
A1: Sensitivity analysis - intrinsic value per share ($)
A2: Closed-form formulas (no data tables) so they recalculate live for the selected scenario. Green = at or above current price; red = below.
A3: Current share price | B3: =Assumptions!B9 -> 226.32
A5: Table 1: WACC vs terminal growth (perpetuity-growth method)
A6: WACC (down) / terminal growth (across) | C6: =DCF!$B$16+(-0.01) -> 0.025 | D6: =DCF!$B$16+(-0.005) -> 0.03 | E6: =DCF!$B$16+(0) -> 0.035 | F6: =DCF!$B$16+(0.005) -> 0.04 | G6: =DCF!$B$16+(0.01) -> 0.045
B7: =DCF!$B$14+(-0.015) -> 0.10352934 | C7: =(SUMPRODUCT(DCF!$E$7:$N$7/(1+$B7)^DCF!$E$8:$N$8)+Forecast!$N$7*(1+C$6)*Forecast!$N$8*(1-Forecast!$N$13)*(1-C$6/DCF!$B$17)/($B7-C$6)/(1+$B7)^DCF!$B$27+DCF!$B$55)/Assumptions!$B$10 -> 208.61916 | D7: =(SUMPRODUCT(DCF!$E$7:$N$7/(1+$B7)^DCF!$E$8:$N$8)+Forecast!$N$7*(1+D$6)*Forecast!$N$8*(1-Forecast!$N$13)*(1-D$6/DCF!$B$17)/($B7-D$6)/(1+$B7)^DCF!$B$27+DCF!$B$55)/Assumptions!$B$10 -> 214.35954 | E7: =(SUMPRODUCT(DCF!$E$7:$N$7/(1+$B7)^DCF!$E$8:$N$8)+Forecast!$N$7*(1+E$6)*Forecast!$N$8*(1-Forecast!$N$13)*(1-E$6/DCF!$B$17)/($B7-E$6)/(1+$B7)^DCF!$B$27+DCF!$B$55)/Assumptions!$B$10 -> 220.91584 | F7: =(SUMPRODUCT(DCF!$E$7:$N$7/(1+$B7)^DCF!$E$8:$N$8)+Forecast!$N$7*(1+F$6)*Forecast!$N$8*(1-Forecast!$N$13)*(1-F$6/DCF!$B$17)/($B7-F$6)/(1+$B7)^DCF!$B$27+DCF!$B$55)/Assumptions!$B$10 -> 228.48071 | G7: =(SUMPRODUCT(DCF!$E$7:$N$7/(1+$B7)^DCF!$E$8:$N$8)+Forecast!$N$7*(1+G$6)*Forecast!$N$8*(1-Forecast!$N$13)*(1-G$6/DCF!$B$17)/($B7-G$6)/(1+$B7)^DCF!$B$27+DCF!$B$55)/Assumptions!$B$10 -> 237.31263
B8: =DCF!$B$14+(-0.01) -> 0.10852934 | C8: =(SUMPRODUCT(DCF!$E$7:$N$7/(1+$B8)^DCF!$E$8:$N$8)+Forecast!$N$7*(1+C$6)*Forecast!$N$8*(1-Forecast!$N$13)*(1-C$6/DCF!$B$17)/($B8-C$6)/(1+$B8)^DCF!$B$27+DCF!$B$55)/Assumptions!$B$10 -> 196.32547 | D8: =(SUMPRODUCT(DCF!$E$7:$N$7/(1+$B8)^DCF!$E$8:$N$8)+Forecast!$N$7*(1+D$6)*Forecast!$N$8*(1-Forecast!$N$13)*(1-D$6/DCF!$B$17)/($B8-D$6)/(1+$B8)^DCF!$B$27+DCF!$B$55)/Assumptions!$B$10 -> 201.09915 | E8: =(SUMPRODUCT(DCF!$E$7:$N$7/(1+$B8)^DCF!$E$8:$N$8)+Forecast!$N$7*(1+E$6)*Forecast!$N$8*(1-Forecast!$N$13)*(1-E$6/DCF!$B$17)/($B8-E$6)/(1+$B8)^DCF!$B$27+DCF!$B$55)/Assumptions!$B$10 -> 206.50259 | F8: =(SUMPRODUCT(DCF!$E$7:$N$7/(1+$B8)^DCF!$E$8:$N$8)+Forecast!$N$7*(1+F$6)*Forecast!$N$8*(1-Forecast!$N$13)*(1-F$6/DCF!$B$17)/($B8-F$6)/(1+$B8)^DCF!$B$27+DCF!$B$55)/Assumptions!$B$10 -> 212.67364 | G8: =(SUMPRODUCT(DCF!$E$7:$N$7/(1+$B8)^DCF!$E$8:$N$8)+Forecast!$N$7*(1+G$6)*Forecast!$N$8*(1-Forecast!$N$13)*(1-G$6/DCF!$B$17)/($B8-G$6)/(1+$B8)^DCF!$B$27+DCF!$B$55)/Assumptions!$B$10 -> 219.79353
B9: =DCF!$B$14+(-0.005) -> 0.11352934 | C9: =(SUMPRODUCT(DCF!$E$7:$N$7/(1+$B9)^DCF!$E$8:$N$8)+Forecast!$N$7*(1+C$6)*Forecast!$N$8*(1-Forecast!$N$13)*(1-C$6/DCF!$B$17)/($B9-C$6)/(1+$B9)^DCF!$B$27+DCF!$B$55)/Assumptions!$B$10 -> 185.41844 | D9: =(SUMPRODUCT(DCF!$E$7:$N$7/(1+$B9)^DCF!$E$8:$N$8)+Forecast!$N$7*(1+D$6)*Forecast!$N$8*(1-Forecast!$N$13)*(1-D$6/DCF!$B$17)/($B9-D$6)/(1+$B9)^DCF!$B$27+DCF!$B$55)/Assumptions!$B$10 -> 189.41824 | E9: =(SUMPRODUCT(DCF!$E$7:$N$7/(1+$B9)^DCF!$E$8:$N$8)+Forecast!$N$7*(1+E$6)*Forecast!$N$8*(1-Forecast!$N$13)*(1-E$6/DCF!$B$17)/($B9-E$6)/(1+$B9)^DCF!$B$27+DCF!$B$55)/Assumptions!$B$10 -> 193.90986 | F9: =(SUMPRODUCT(DCF!$E$7:$N$7/(1+$B9)^DCF!$E$8:$N$8)+Forecast!$N$7*(1+F$6)*Forecast!$N$8*(1-Forecast!$N$13)*(1-F$6/DCF!$B$17)/($B9-F$6)/(1+$B9)^DCF!$B$27+DCF!$B$55)/Assumptions!$B$10 -> 198.99364 | G9: =(SUMPRODUCT(DCF!$E$7:$N$7/(1+$B9)^DCF!$E$8:$N$8)+Forecast!$N$7*(1+G$6)*Forecast!$N$8*(1-Forecast!$N$13)*(1-G$6/DCF!$B$17)/($B9-G$6)/(1+$B9)^DCF!$B$27+DCF!$B$55)/Assumptions!$B$10 -> 204.79918
B10: =DCF!$B$14+(0) -> 0.11852934 | C10: =(SUMPRODUCT(DCF!$E$7:$N$7/(1+$B10)^DCF!$E$8:$N$8)+Forecast!$N$7*(1+C$6)*Forecast!$N$8*(1-Forecast!$N$13)*(1-C$6/DCF!$B$17)/($B10-C$6)/(1+$B10)^DCF!$B$27+DCF!$B$55)/Assumptions!$B$10 -> 175.67595 | D10: =(SUMPRODUCT(DCF!$E$7:$N$7/(1+$B10)^DCF!$E$8:$N$8)+Forecast!$N$7*(1+D$6)*Forecast!$N$8*(1-Forecast!$N$13)*(1-D$6/DCF!$B$17)/($B10-D$6)/(1+$B10)^DCF!$B$27+DCF!$B$55)/Assumptions!$B$10 -> 179.0497 | E10: =(SUMPRODUCT(DCF!$E$7:$N$7/(1+$B10)^DCF!$E$8:$N$8)+Forecast!$N$7*(1+E$6)*Forecast!$N$8*(1-Forecast!$N$13)*(1-E$6/DCF!$B$17)/($B10-E$6)/(1+$B10)^DCF!$B$27+DCF!$B$55)/Assumptions!$B$10 -> 182.81152 | F10: =(SUMPRODUCT(DCF!$E$7:$N$7/(1+$B10)^DCF!$E$8:$N$8)+Forecast!$N$7*(1+F$6)*Forecast!$N$8*(1-Forecast!$N$13)*(1-F$6/DCF!$B$17)/($B10-F$6)/(1+$B10)^DCF!$B$27+DCF!$B$55)/Assumptions!$B$10 -> 187.03553 | G10: =(SUMPRODUCT(DCF!$E$7:$N$7/(1+$B10)^DCF!$E$8:$N$8)+Forecast!$N$7*(1+G$6)*Forecast!$N$8*(1-Forecast!$N$13)*(1-G$6/DCF!$B$17)/($B10-G$6)/(1+$B10)^DCF!$B$27+DCF!$B$55)/Assumptions!$B$10 -> 191.81602
B11: =DCF!$B$14+(0.005) -> 0.12352934 | C11: =(SUMPRODUCT(DCF!$E$7:$N$7/(1+$B11)^DCF!$E$8:$N$8)+Forecast!$N$7*(1+C$6)*Forecast!$N$8*(1-Forecast!$N$13)*(1-C$6/DCF!$B$17)/($B11-C$6)/(1+$B11)^DCF!$B$27+DCF!$B$55)/Assumptions!$B$10 -> 166.92097 | D11: =(SUMPRODUCT(DCF!$E$7:$N$7/(1+$B11)^DCF!$E$8:$N$8)+Forecast!$N$7*(1+D$6)*Forecast!$N$8*(1-Forecast!$N$13)*(1-D$6/DCF!$B$17)/($B11-D$6)/(1+$B11)^DCF!$B$27+DCF!$B$55)/Assumptions!$B$10 -> 169.78353 | E11: =(SUMPRODUCT(DCF!$E$7:$N$7/(1+$B11)^DCF!$E$8:$N$8)+Forecast!$N$7*(1+E$6)*Forecast!$N$8*(1-Forecast!$N$13)*(1-E$6/DCF!$B$17)/($B11-E$6)/(1+$B11)^DCF!$B$27+DCF!$B$55)/Assumptions!$B$10 -> 172.95508 | F11: =(SUMPRODUCT(DCF!$E$7:$N$7/(1+$B11)^DCF!$E$8:$N$8)+Forecast!$N$7*(1+F$6)*Forecast!$N$8*(1-Forecast!$N$13)*(1-F$6/DCF!$B$17)/($B11-F$6)/(1+$B11)^DCF!$B$27+DCF!$B$55)/Assumptions!$B$10 -> 176.4911 | G11: =(SUMPRODUCT(DCF!$E$7:$N$7/(1+$B11)^DCF!$E$8:$N$8)+Forecast!$N$7*(1+G$6)*Forecast!$N$8*(1-Forecast!$N$13)*(1-G$6/DCF!$B$17)/($B11-G$6)/(1+$B11)^DCF!$B$27+DCF!$B$55)/Assumptions!$B$10 -> 180.46121
B12: =DCF!$B$14+(0.01) -> 0.12852934 | C12: =(SUMPRODUCT(DCF!$E$7:$N$7/(1+$B12)^DCF!$E$8:$N$8)+Forecast!$N$7*(1+C$6)*Forecast!$N$8*(1-Forecast!$N$13)*(1-C$6/DCF!$B$17)/($B12-C$6)/(1+$B12)^DCF!$B$27+DCF!$B$55)/Assumptions!$B$10 -> 159.01062 | D12: =(SUMPRODUCT(DCF!$E$7:$N$7/(1+$B12)^DCF!$E$8:$N$8)+Forecast!$N$7*(1+D$6)*Forecast!$N$8*(1-Forecast!$N$13)*(1-D$6/DCF!$B$17)/($B12-D$6)/(1+$B12)^DCF!$B$27+DCF!$B$55)/Assumptions!$B$10 -> 161.45232 | E12: =(SUMPRODUCT(DCF!$E$7:$N$7/(1+$B12)^DCF!$E$8:$N$8)+Forecast!$N$7*(1+E$6)*Forecast!$N$8*(1-Forecast!$N$13)*(1-E$6/DCF!$B$17)/($B12-E$6)/(1+$B12)^DCF!$B$27+DCF!$B$55)/Assumptions!$B$10 -> 164.14201 | F12: =(SUMPRODUCT(DCF!$E$7:$N$7/(1+$B12)^DCF!$E$8:$N$8)+Forecast!$N$7*(1+F$6)*Forecast!$N$8*(1-Forecast!$N$13)*(1-F$6/DCF!$B$17)/($B12-F$6)/(1+$B12)^DCF!$B$27+DCF!$B$55)/Assumptions!$B$10 -> 167.12171 | G12: =(SUMPRODUCT(DCF!$E$7:$N$7/(1+$B12)^DCF!$E$8:$N$8)+Forecast!$N$7*(1+G$6)*Forecast!$N$8*(1-Forecast!$N$13)*(1-G$6/DCF!$B$17)/($B12-G$6)/(1+$B12)^DCF!$B$27+DCF!$B$55)/Assumptions!$B$10 -> 170.4435
B13: =DCF!$B$14+(0.015) -> 0.13352934 | C13: =(SUMPRODUCT(DCF!$E$7:$N$7/(1+$B13)^DCF!$E$8:$N$8)+Forecast!$N$7*(1+C$6)*Forecast!$N$8*(1-Forecast!$N$13)*(1-C$6/DCF!$B$17)/($B13-C$6)/(1+$B13)^DCF!$B$27+DCF!$B$55)/Assumptions!$B$10 -> 151.82838 | D13: =(SUMPRODUCT(DCF!$E$7:$N$7/(1+$B13)^DCF!$E$8:$N$8)+Forecast!$N$7*(1+D$6)*Forecast!$N$8*(1-Forecast!$N$13)*(1-D$6/DCF!$B$17)/($B13-D$6)/(1+$B13)^DCF!$B$27+DCF!$B$55)/Assumptions!$B$10 -> 153.92099 | E13: =(SUMPRODUCT(DCF!$E$7:$N$7/(1+$B13)^DCF!$E$8:$N$8)+Forecast!$N$7*(1+E$6)*Forecast!$N$8*(1-Forecast!$N$13)*(1-E$6/DCF!$B$17)/($B13-E$6)/(1+$B13)^DCF!$B$27+DCF!$B$55)/Assumptions!$B$10 -> 156.21406 | F13: =(SUMPRODUCT(DCF!$E$7:$N$7/(1+$B13)^DCF!$E$8:$N$8)+Forecast!$N$7*(1+F$6)*Forecast!$N$8*(1-Forecast!$N$13)*(1-F$6/DCF!$B$17)/($B13-F$6)/(1+$B13)^DCF!$B$27+DCF!$B$55)/Assumptions!$B$10 -> 158.73972 | G13: =(SUMPRODUCT(DCF!$E$7:$N$7/(1+$B13)^DCF!$E$8:$N$8)+Forecast!$N$7*(1+G$6)*Forecast!$N$8*(1-Forecast!$N$13)*(1-G$6/DCF!$B$17)/($B13-G$6)/(1+$B13)^DCF!$B$27+DCF!$B$55)/Assumptions!$B$10 -> 161.53739
A16: Table 2: WACC vs exit EV/EBITDA multiple (exit-multiple method)
A17: WACC (down) / exit multiple (across) | C17: =DCF!$B$18+(-4) -> 10 | D17: =DCF!$B$18+(-2) -> 12 | E17: =DCF!$B$18+(0) -> 14 | F17: =DCF!$B$18+(2) -> 16 | G17: =DCF!$B$18+(4) -> 18
B18: =DCF!$B$14+(-0.015) -> 0.10352934 | C18: =(SUMPRODUCT(DCF!$E$7:$N$7/(1+$B18)^DCF!$E$8:$N$8)+DCF!$B$34*C$17/(1+$B18)^DCF!$B$37+DCF!$B$55)/Assumptions!$B$10 -> 211.18936 | D18: =(SUMPRODUCT(DCF!$E$7:$N$7/(1+$B18)^DCF!$E$8:$N$8)+DCF!$B$34*D$17/(1+$B18)^DCF!$B$37+DCF!$B$55)/Assumptions!$B$10 -> 233.08406 | E18: =(SUMPRODUCT(DCF!$E$7:$N$7/(1+$B18)^DCF!$E$8:$N$8)+DCF!$B$34*E$17/(1+$B18)^DCF!$B$37+DCF!$B$55)/Assumptions!$B$10 -> 254.97876 | F18: =(SUMPRODUCT(DCF!$E$7:$N$7/(1+$B18)^DCF!$E$8:$N$8)+DCF!$B$34*F$17/(1+$B18)^DCF!$B$37+DCF!$B$55)/Assumptions!$B$10 -> 276.87346 | G18: =(SUMPRODUCT(DCF!$E$7:$N$7/(1+$B18)^DCF!$E$8:$N$8)+DCF!$B$34*G$17/(1+$B18)^DCF!$B$37+DCF!$B$55)/Assumptions!$B$10 -> 298.76816
B19: =DCF!$B$14+(-0.01) -> 0.10852934 | C19: =(SUMPRODUCT(DCF!$E$7:$N$7/(1+$B19)^DCF!$E$8:$N$8)+DCF!$B$34*C$17/(1+$B19)^DCF!$B$37+DCF!$B$55)/Assumptions!$B$10 -> 204.70742 | D19: =(SUMPRODUCT(DCF!$E$7:$N$7/(1+$B19)^DCF!$E$8:$N$8)+DCF!$B$34*D$17/(1+$B19)^DCF!$B$37+DCF!$B$55)/Assumptions!$B$10 -> 225.70057 | E19: =(SUMPRODUCT(DCF!$E$7:$N$7/(1+$B19)^DCF!$E$8:$N$8)+DCF!$B$34*E$17/(1+$B19)^DCF!$B$37+DCF!$B$55)/Assumptions!$B$10 -> 246.69371 | F19: =(SUMPRODUCT(DCF!$E$7:$N$7/(1+$B19)^DCF!$E$8:$N$8)+DCF!$B$34*F$17/(1+$B19)^DCF!$B$37+DCF!$B$55)/Assumptions!$B$10 -> 267.68686 | G19: =(SUMPRODUCT(DCF!$E$7:$N$7/(1+$B19)^DCF!$E$8:$N$8)+DCF!$B$34*G$17/(1+$B19)^DCF!$B$37+DCF!$B$55)/Assumptions!$B$10 -> 288.68001
B20: =DCF!$B$14+(-0.005) -> 0.11352934 | C20: =(SUMPRODUCT(DCF!$E$7:$N$7/(1+$B20)^DCF!$E$8:$N$8)+DCF!$B$34*C$17/(1+$B20)^DCF!$B$37+DCF!$B$55)/Assumptions!$B$10 -> 198.49117 | D20: =(SUMPRODUCT(DCF!$E$7:$N$7/(1+$B20)^DCF!$E$8:$N$8)+DCF!$B$34*D$17/(1+$B20)^DCF!$B$37+DCF!$B$55)/Assumptions!$B$10 -> 218.6237 | E20: =(SUMPRODUCT(DCF!$E$7:$N$7/(1+$B20)^DCF!$E$8:$N$8)+DCF!$B$34*E$17/(1+$B20)^DCF!$B$37+DCF!$B$55)/Assumptions!$B$10 -> 238.75623 | F20: =(SUMPRODUCT(DCF!$E$7:$N$7/(1+$B20)^DCF!$E$8:$N$8)+DCF!$B$34*F$17/(1+$B20)^DCF!$B$37+DCF!$B$55)/Assumptions!$B$10 -> 258.88875 | G20: =(SUMPRODUCT(DCF!$E$7:$N$7/(1+$B20)^DCF!$E$8:$N$8)+DCF!$B$34*G$17/(1+$B20)^DCF!$B$37+DCF!$B$55)/Assumptions!$B$10 -> 279.02128
B21: =DCF!$B$14+(0) -> 0.11852934 | C21: =(SUMPRODUCT(DCF!$E$7:$N$7/(1+$B21)^DCF!$E$8:$N$8)+DCF!$B$34*C$17/(1+$B21)^DCF!$B$37+DCF!$B$55)/Assumptions!$B$10 -> 192.52814 | D21: =(SUMPRODUCT(DCF!$E$7:$N$7/(1+$B21)^DCF!$E$8:$N$8)+DCF!$B$34*D$17/(1+$B21)^DCF!$B$37+DCF!$B$55)/Assumptions!$B$10 -> 211.83895 | E21: =(SUMPRODUCT(DCF!$E$7:$N$7/(1+$B21)^DCF!$E$8:$N$8)+DCF!$B$34*E$17/(1+$B21)^DCF!$B$37+DCF!$B$55)/Assumptions!$B$10 -> 231.14976 | F21: =(SUMPRODUCT(DCF!$E$7:$N$7/(1+$B21)^DCF!$E$8:$N$8)+DCF!$B$34*F$17/(1+$B21)^DCF!$B$37+DCF!$B$55)/Assumptions!$B$10 -> 250.46057 | G21: =(SUMPRODUCT(DCF!$E$7:$N$7/(1+$B21)^DCF!$E$8:$N$8)+DCF!$B$34*G$17/(1+$B21)^DCF!$B$37+DCF!$B$55)/Assumptions!$B$10 -> 269.77138
B22: =DCF!$B$14+(0.005) -> 0.12352934 | C22: =(SUMPRODUCT(DCF!$E$7:$N$7/(1+$B22)^DCF!$E$8:$N$8)+DCF!$B$34*C$17/(1+$B22)^DCF!$B$37+DCF!$B$55)/Assumptions!$B$10 -> 186.8065 | D22: =(SUMPRODUCT(DCF!$E$7:$N$7/(1+$B22)^DCF!$E$8:$N$8)+DCF!$B$34*D$17/(1+$B22)^DCF!$B$37+DCF!$B$55)/Assumptions!$B$10 -> 205.33257 | E22: =(SUMPRODUCT(DCF!$E$7:$N$7/(1+$B22)^DCF!$E$8:$N$8)+DCF!$B$34*E$17/(1+$B22)^DCF!$B$37+DCF!$B$55)/Assumptions!$B$10 -> 223.85864 | F22: =(SUMPRODUCT(DCF!$E$7:$N$7/(1+$B22)^DCF!$E$8:$N$8)+DCF!$B$34*F$17/(1+$B22)^DCF!$B$37+DCF!$B$55)/Assumptions!$B$10 -> 242.38472 | G22: =(SUMPRODUCT(DCF!$E$7:$N$7/(1+$B22)^DCF!$E$8:$N$8)+DCF!$B$34*G$17/(1+$B22)^DCF!$B$37+DCF!$B$55)/Assumptions!$B$10 -> 260.91079
B23: =DCF!$B$14+(0.01) -> 0.12852934 | C23: =(SUMPRODUCT(DCF!$E$7:$N$7/(1+$B23)^DCF!$E$8:$N$8)+DCF!$B$34*C$17/(1+$B23)^DCF!$B$37+DCF!$B$55)/Assumptions!$B$10 -> 181.31503 | D23: =(SUMPRODUCT(DCF!$E$7:$N$7/(1+$B23)^DCF!$E$8:$N$8)+DCF!$B$34*D$17/(1+$B23)^DCF!$B$37+DCF!$B$55)/Assumptions!$B$10 -> 199.09153 | E23: =(SUMPRODUCT(DCF!$E$7:$N$7/(1+$B23)^DCF!$E$8:$N$8)+DCF!$B$34*E$17/(1+$B23)^DCF!$B$37+DCF!$B$55)/Assumptions!$B$10 -> 216.86803 | F23: =(SUMPRODUCT(DCF!$E$7:$N$7/(1+$B23)^DCF!$E$8:$N$8)+DCF!$B$34*F$17/(1+$B23)^DCF!$B$37+DCF!$B$55)/Assumptions!$B$10 -> 234.64453 | G23: =(SUMPRODUCT(DCF!$E$7:$N$7/(1+$B23)^DCF!$E$8:$N$8)+DCF!$B$34*G$17/(1+$B23)^DCF!$B$37+DCF!$B$55)/Assumptions!$B$10 -> 252.42103
B24: =DCF!$B$14+(0.015) -> 0.13352934 | C24: =(SUMPRODUCT(DCF!$E$7:$N$7/(1+$B24)^DCF!$E$8:$N$8)+DCF!$B$34*C$17/(1+$B24)^DCF!$B$37+DCF!$B$55)/Assumptions!$B$10 -> 176.04309 | D24: =(SUMPRODUCT(DCF!$E$7:$N$7/(1+$B24)^DCF!$E$8:$N$8)+DCF!$B$34*D$17/(1+$B24)^DCF!$B$37+DCF!$B$55)/Assumptions!$B$10 -> 193.10346 | E24: =(SUMPRODUCT(DCF!$E$7:$N$7/(1+$B24)^DCF!$E$8:$N$8)+DCF!$B$34*E$17/(1+$B24)^DCF!$B$37+DCF!$B$55)/Assumptions!$B$10 -> 210.16383 | F24: =(SUMPRODUCT(DCF!$E$7:$N$7/(1+$B24)^DCF!$E$8:$N$8)+DCF!$B$34*F$17/(1+$B24)^DCF!$B$37+DCF!$B$55)/Assumptions!$B$10 -> 227.2242 | G24: =(SUMPRODUCT(DCF!$E$7:$N$7/(1+$B24)^DCF!$E$8:$N$8)+DCF!$B$34*G$17/(1+$B24)^DCF!$B$37+DCF!$B$55)/Assumptions!$B$10 -> 244.28457
A27: Table 3: Beta vs equity risk premium -> WACC, and blended value impact is shown via Tables 1-2
A28: Cost of equity / WACC (beta down, ERP across) | C28: 0.04 | D28: 0.045 | E28: 0.05 | F28: 0.055
B29: 1.2 | C29: =WACC!$B$17*(WACC!$B$4+$B29*C$28)+WACC!$B$18*WACC!$B$12 -> 0.094674157 | D29: =WACC!$B$17*(WACC!$B$4+$B29*D$28)+WACC!$B$18*WACC!$B$12 -> 0.10063795 | E29: =WACC!$B$17*(WACC!$B$4+$B29*E$28)+WACC!$B$18*WACC!$B$12 -> 0.10660175 | F29: =WACC!$B$17*(WACC!$B$4+$B29*F$28)+WACC!$B$18*WACC!$B$12 -> 0.11256554
B30: 1.4 | C30: =WACC!$B$17*(WACC!$B$4+$B30*C$28)+WACC!$B$18*WACC!$B$12 -> 0.10262588 | D30: =WACC!$B$17*(WACC!$B$4+$B30*D$28)+WACC!$B$18*WACC!$B$12 -> 0.10958365 | E30: =WACC!$B$17*(WACC!$B$4+$B30*E$28)+WACC!$B$18*WACC!$B$12 -> 0.11654141 | F30: =WACC!$B$17*(WACC!$B$4+$B30*F$28)+WACC!$B$18*WACC!$B$12 -> 0.12349917
B31: 1.6 | C31: =WACC!$B$17*(WACC!$B$4+$B31*C$28)+WACC!$B$18*WACC!$B$12 -> 0.11057761 | D31: =WACC!$B$17*(WACC!$B$4+$B31*D$28)+WACC!$B$18*WACC!$B$12 -> 0.11852934 | E31: =WACC!$B$17*(WACC!$B$4+$B31*E$28)+WACC!$B$18*WACC!$B$12 -> 0.12648106 | F31: =WACC!$B$17*(WACC!$B$4+$B31*F$28)+WACC!$B$18*WACC!$B$12 -> 0.13443279
B32: 1.8 | C32: =WACC!$B$17*(WACC!$B$4+$B32*C$28)+WACC!$B$18*WACC!$B$12 -> 0.11852934 | D32: =WACC!$B$17*(WACC!$B$4+$B32*D$28)+WACC!$B$18*WACC!$B$12 -> 0.12747503 | E32: =WACC!$B$17*(WACC!$B$4+$B32*E$28)+WACC!$B$18*WACC!$B$12 -> 0.13642072 | F32: =WACC!$B$17*(WACC!$B$4+$B32*F$28)+WACC!$B$18*WACC!$B$12 -> 0.14536642
B33: 2 | C33: =WACC!$B$17*(WACC!$B$4+$B33*C$28)+WACC!$B$18*WACC!$B$12 -> 0.12648106 | D33: =WACC!$B$17*(WACC!$B$4+$B33*D$28)+WACC!$B$18*WACC!$B$12 -> 0.13642072 | E33: =WACC!$B$17*(WACC!$B$4+$B33*E$28)+WACC!$B$18*WACC!$B$12 -> 0.14636038 | F33: =WACC!$B$17*(WACC!$B$4+$B33*F$28)+WACC!$B$18*WACC!$B$12 -> 0.15630004
B34: 2.22 | C34: =WACC!$B$17*(WACC!$B$4+$B34*C$28)+WACC!$B$18*WACC!$B$12 -> 0.13522796 | D34: =WACC!$B$17*(WACC!$B$4+$B34*D$28)+WACC!$B$18*WACC!$B$12 -> 0.14626099 | E34: =WACC!$B$17*(WACC!$B$4+$B34*E$28)+WACC!$B$18*WACC!$B$12 -> 0.15729401 | F34: =WACC!$B$17*(WACC!$B$4+$B34*F$28)+WACC!$B$18*WACC!$B$12 -> 0.16832703

Sheet Scenarios
A1: Scenario engine - Bear / Base / Bull computed in parallel
A2: Each block re-runs the DCF with that scenario's drivers (same WACC), so the probability-weighted value does not depend on the selector.
A4: Scenario summary | B4: Value/share (perp. growth) | C4: Value/share (exit mult.) | D4: Blended value/share | E4: Upside vs price | F4: Probability
A5: Bear | B5: =B28 -> 68.778436 | C5: =B31 -> 74.82811 | D5: =B32 -> 71.803273 | E5: =D5/Assumptions!$B$9-1 -> -0.68273563 | F5: =Assumptions!B19 -> 0.25
A6: Base | B6: =B50 -> 182.81152 | C6: =B53 -> 231.14976 | D6: =B54 -> 206.98064 | E6: =D6/Assumptions!$B$9-1 -> -0.085451407 | F6: =Assumptions!B20 -> 0.5
A7: Bull | B7: =B72 -> 264.29774 | C7: =B75 -> 378.46538 | D7: =B76 -> 321.38156 | E7: =D7/Assumptions!$B$9-1 -> 0.42003164 | F7: =Assumptions!B21 -> 0.25
A8: Probability-weighted value per share | D8: =SUMPRODUCT(D5:D7,F5:F7) -> 201.78653 | E8: =D8/Assumptions!$B$9-1 -> -0.1084017 | F8: =SUM(F5:F7) -> 1
A9: Current share price | D9: =Assumptions!B9 -> 226.32
A14: Bear case | E14: =Forecast!E4 -> FY2027E | F14: =Forecast!F4 -> FY2028E | G14: =Forecast!G4 -> FY2029E | H14: =Forecast!H4 -> FY2030E | I14: =Forecast!I4 -> FY2031E | J14: =Forecast!J4 -> FY2032E | K14: =Forecast!K4 -> FY2033E | L14: =Forecast!L4 -> FY2034E | ... N14: =Forecast!N4 -> FY2036E
A15: Revenue | E15: =Forecast!$D$7*(1+Assumptions!E28) -> 388688.4 | F15: =E15*(1+Assumptions!F28) -> 446991.66 | G15: =F15*(1+Assumptions!G28) -> 469341.24 | H15: =G15*(1+Assumptions!H28) -> 478728.07 | I15: =H15*(1+Assumptions!I28) -> 493089.91 | J15: =I15*(1+Assumptions!J28) -> 512813.51 | K15: =J15*(1+Assumptions!K28) -> 533326.05 | L15: =K15*(1+Assumptions!L28) -> 554659.09 | M15: =L15*(1+Assumptions!M28) -> 574072.16 | N15: =M15*(1+Assumptions!N28) -> 591294.32
A16: EBIT | E16: =E15*Assumptions!E35 -> 248760.58 | F16: =F15*Assumptions!F35 -> 259255.16 | G16: =G15*Assumptions!G35 -> 244057.45 | H16: =H15*Assumptions!H35 -> 220214.91 | I16: =I15*Assumptions!I35 -> 207097.76 | J16: =J15*Assumptions!J35 -> 199997.27 | K16: =K15*Assumptions!K35 -> 197330.64 | L16: =L15*Assumptions!L35 -> 194130.68 | ... N16: =N15*Assumptions!N35 -> 195127.13
A17: EBITDA | E17: =E16+E15*Assumptions!E$43 -> 253424.84 | F17: =F16+F15*Assumptions!F$43 -> 264619.06 | G17: =G16+G15*Assumptions!G$43 -> 250158.88 | H17: =H16+H15*Assumptions!H$43 -> 226917.1 | I17: =I16+I15*Assumptions!I$43 -> 214494.11 | J17: =J16+J15*Assumptions!J$43 -> 208202.28 | K17: =K16+K15*Assumptions!K$43 -> 206397.18 | L17: =L16+L15*Assumptions!L$43 -> 204114.54 | ... N17: =N16+N15*Assumptions!N$43 -> 206953.01
A18: NOPAT | E18: =E16*(1-Assumptions!E$42) -> 206471.28 | F18: =F16*(1-Assumptions!F$42) -> 212589.23 | G18: =G16*(1-Assumptions!G$42) -> 200127.11 | H18: =H16*(1-Assumptions!H$42) -> 180576.23 | I18: =I16*(1-Assumptions!I$42) -> 169820.16 | J18: =J16*(1-Assumptions!J$42) -> 161997.79 | K18: =K16*(1-Assumptions!K$42) -> 159837.82 | L18: =L16*(1-Assumptions!L$42) -> 157245.85 | ... N18: =N16*(1-Assumptions!N$42) -> 158052.97
A19: Net capex (capex - D&A) | E19: =E15*(Assumptions!E$44-Assumptions!E$43) -> 5052.9492 | F19: =F15*(Assumptions!F$44-Assumptions!F$43) -> 6257.8832 | G19: =G15*(Assumptions!G$44-Assumptions!G$43) -> 6101.4362 | H19: =H15*(Assumptions!H$44-Assumptions!H$43) -> 5744.7368 | I19: =I15*(Assumptions!I$44-Assumptions!I$43) -> 5423.989 | J19: =J15*(Assumptions!J$44-Assumptions!J$43) -> 4615.3216 | K19: =K15*(Assumptions!K$44-Assumptions!K$43) -> 4266.6084 | L19: =L15*(Assumptions!L$44-Assumptions!L$43) -> 3327.9545 | ... N19: =N15*(Assumptions!N$44-Assumptions!N$43) -> 2365.1773
A20: Operating NWC | E20: =E15*Assumptions!$B$22 -> 56962.684 | F20: =F15*Assumptions!$B$22 -> 65507.087 | G20: =G15*Assumptions!$B$22 -> 68782.441 | H20: =H15*Assumptions!$B$22 -> 70158.09 | I20: =I15*Assumptions!$B$22 -> 72262.833 | J20: =J15*Assumptions!$B$22 -> 75153.346 | K20: =K15*Assumptions!$B$22 -> 78159.48 | L20: =L15*Assumptions!$B$22 -> 81285.859 | ... N20: =N15*Assumptions!$B$22 -> 86654.79
A21: Increase in NWC | E21: =E20-Forecast!$D$19 -> 25077.684 | F21: =F20-E20 -> 8544.4026 | G21: =G20-F20 -> 3275.3543 | H21: =H20-G20 -> 1375.6488 | I21: =I20-H20 -> 2104.7427 | J21: =J20-I20 -> 2890.5133 | K21: =K20-J20 -> 3006.1338 | L21: =L20-K20 -> 3126.3792 | M21: =M20-L20 -> 2845.0051 | N21: =N20-M20 -> 2523.9259
A22: FCFF | E22: =E18-E19-E21 -> 176340.64 | F22: =F18-F19-F21 -> 197786.95 | G22: =G18-G19-G21 -> 190750.32 | H22: =H18-H19-H21 -> 173455.84 | I22: =I18-I19-I21 -> 162291.43 | J22: =J18-J19-J21 -> 154491.95 | K22: =K18-K19-K21 -> 152565.07 | L22: =L18-L19-L21 -> 150791.52 | ... N22: =N18-N19-N21 -> 153163.87
A23: PV of FCFF (stub-adjusted) | E23: =E22*DCF!E$6*DCF!E$9 -> 52254.274 | F23: =F22*DCF!F$6*DCF!F$9 -> 180806.1 | G23: =G22*DCF!G$6*DCF!G$9 -> 155895.41 | H23: =H22*DCF!H$6*DCF!H$9 -> 126738.81 | I23: =I22*DCF!I$6*DCF!I$9 -> 106015.39 | J23: =J22*DCF!J$6*DCF!J$9 -> 90226.019 | K23: =K22*DCF!K$6*DCF!K$9 -> 79658.786 | L23: =L22*DCF!L$6*DCF!L$9 -> 70389.534 | ... N23: =N22*DCF!N$6*DCF!N$9 -> 57146.909
A25: Sum of PV of FCFF | B25: =SUM(E23:N23) -> 982726.31
A26: PV of TV - perpetuity growth | B26: =N15*(1+Assumptions!$B$49)*Assumptions!N35*(1-Assumptions!N$42)*(1-Assumptions!$B$49/Assumptions!$B$50)/(DCF!$B$14-Assumptions!$B$49)/(1+DCF!$B$14)^DCF!$B$27 -> 583187.25
A27: Enterprise value - perpetuity growth | B27: =B25+B26 -> 1565913.6
A28: Value per share - perpetuity growth | B28: =(B27+DCF!$B$55)/Assumptions!$B$10 -> 68.778436
A29: PV of TV - exit multiple | B29: =N17*Assumptions!$B$51/(1+DCF!$B$14)^DCF!$B$37 -> 730103.58
A30: Enterprise value - exit multiple | B30: =B25+B29 -> 1712829.9
A31: Value per share - exit multiple | B31: =(B30+DCF!$B$55)/Assumptions!$B$10 -> 74.82811
A32: Blended value per share | B32: =Assumptions!$B$18*B28+(1-Assumptions!$B$18)*B31 -> 71.803273
A33: FY2036E revenue | B33: =N15 -> 591294.32
A36: Base case | E36: =Forecast!E4 -> FY2027E | F36: =Forecast!F4 -> FY2028E | G36: =Forecast!G4 -> FY2029E | H36: =Forecast!H4 -> FY2030E | I36: =Forecast!I4 -> FY2031E | J36: =Forecast!J4 -> FY2032E | K36: =Forecast!K4 -> FY2033E | L36: =Forecast!L4 -> FY2034E | ... N36: =Forecast!N4 -> FY2036E
A37: Revenue | E37: =Forecast!$D$7*(1+Assumptions!E29) -> 403804.06 | F37: =E37*(1+Assumptions!F29) -> 557249.6 | G37: =F37*(1+Assumptions!G29) -> 696562 | H37: =G37*(1+Assumptions!H29) -> 821943.16 | I37: =H37*(1+Assumptions!I29) -> 937015.21 | J37: =I37*(1+Assumptions!J29) -> 1040086.9 | K37: =J37*(1+Assumptions!K29) -> 1133694.7 | L37: =K37*(1+Assumptions!L29) -> 1218721.8 | M37: =L37*(1+Assumptions!M29) -> 1291845.1 | N37: =M37*(1+Assumptions!N29) -> 1356437.4
A38: EBIT | E38: =E37*Assumptions!E36 -> 262472.64 | F38: =F37*Assumptions!F36 -> 356639.75 | G38: =G37*Assumptions!G36 -> 431868.44 | H38: =H37*Assumptions!H36 -> 493165.9 | I38: =I37*Assumptions!I36 -> 543468.82 | J38: =J37*Assumptions!J36 -> 572047.78 | K38: =K37*Assumptions!K36 -> 600858.19 | L38: =L37*Assumptions!L36 -> 621548.12 | ... N38: =N37*Assumptions!N36 -> 637525.56
A39: EBITDA | E39: =E38+E37*Assumptions!E$43 -> 267318.29 | F39: =F38+F37*Assumptions!F$43 -> 363326.74 | G39: =G38+G37*Assumptions!G$43 -> 440923.75 | H39: =H38+H37*Assumptions!H$43 -> 504673.1 | I39: =I38+I37*Assumptions!I$43 -> 557524.05 | J39: =J38+J37*Assumptions!J$43 -> 588689.17 | K39: =K38+K37*Assumptions!K$43 -> 620131 | L39: =L38+L37*Assumptions!L$43 -> 643485.11 | ... N39: =N38+N37*Assumptions!N$43 -> 664654.31
A40: NOPAT | E40: =E38*(1-Assumptions!E$42) -> 217852.29 | F40: =F38*(1-Assumptions!F$42) -> 292444.59 | G40: =G38*(1-Assumptions!G$42) -> 354132.12 | H40: =H38*(1-Assumptions!H$42) -> 404396.04 | I40: =I38*(1-Assumptions!I$42) -> 445644.43 | J40: =J38*(1-Assumptions!J$42) -> 463358.7 | K40: =K38*(1-Assumptions!K$42) -> 486695.13 | L40: =L38*(1-Assumptions!L$42) -> 503453.98 | ... N40: =N38*(1-Assumptions!N$42) -> 516395.7
A41: Net capex (capex - D&A) | E41: =E37*(Assumptions!E$44-Assumptions!E$43) -> 5249.4528 | F41: =F37*(Assumptions!F$44-Assumptions!F$43) -> 7801.4944 | G41: =G37*(Assumptions!G$44-Assumptions!G$43) -> 9055.306 | H41: =H37*(Assumptions!H$44-Assumptions!H$43) -> 9863.318 | I41: =I37*(Assumptions!I$44-Assumptions!I$43) -> 10307.167 | J41: =J37*(Assumptions!J$44-Assumptions!J$43) -> 9360.7819 | K41: =K37*(Assumptions!K$44-Assumptions!K$43) -> 9069.5576 | L41: =L37*(Assumptions!L$44-Assumptions!L$43) -> 7312.3308 | ... N41: =N37*(Assumptions!N$44-Assumptions!N$43) -> 5425.7495
A42: Operating NWC | E42: =E37*Assumptions!$B$22 -> 59177.9 | F42: =F37*Assumptions!$B$22 -> 81665.502 | G42: =G37*Assumptions!$B$22 -> 102081.88 | H42: =H37*Assumptions!$B$22 -> 120456.62 | I42: =I37*Assumptions!$B$22 -> 137320.54 | J42: =J37*Assumptions!$B$22 -> 152425.8 | K42: =K37*Assumptions!$B$22 -> 166144.12 | L42: =L37*Assumptions!$B$22 -> 178604.93 | ... N42: =N37*Assumptions!$B$22 -> 198787.29
A43: Increase in NWC | E43: =E42-Forecast!$D$19 -> 27292.9 | F43: =F42-E42 -> 22487.602 | G43: =G42-F42 -> 20416.375 | H43: =H42-G42 -> 18374.738 | I43: =I42-H42 -> 16863.926 | J43: =J42-I42 -> 15105.26 | K43: =K42-J42 -> 13718.322 | L43: =L42-K42 -> 12460.809 | M43: =M42-L42 -> 10716.296 | N43: =N42-M42 -> 9466.0614
A44: FCFF | E44: =E40-E41-E43 -> 185309.94 | F44: =F40-F41-F43 -> 262155.5 | G44: =G40-G41-G43 -> 324660.44 | H44: =H40-H41-H43 -> 376157.98 | I44: =I40-I41-I43 -> 418473.34 | J44: =J40-J41-J43 -> 438892.66 | K44: =K40-K41-K43 -> 463907.25 | L44: =L40-L41-L43 -> 483680.84 | ... N44: =N40-N41-N43 -> 501503.89
A45: PV of FCFF (stub-adjusted) | E45: =E44*DCF!E$6*DCF!E$9 -> 54912.106 | F45: =F44*DCF!F$6*DCF!F$9 -> 239648.34 | G45: =G44*DCF!G$6*DCF!G$9 -> 265336.78 | H45: =H44*DCF!H$6*DCF!H$9 -> 274846.98 | I45: =I44*DCF!I$6*DCF!I$9 -> 273363.87 | J45: =J44*DCF!J$6*DCF!J$9 -> 256321.04 | K45: =K44*DCF!K$6*DCF!K$9 -> 242219.84 | L45: =L44*DCF!L$6*DCF!L$9 -> 225782.39 | ... N45: =N44*DCF!N$6*DCF!N$9 -> 187115.92
A47: Sum of PV of FCFF | B47: =SUM(E45:N45) -> 2226360.4
A48: PV of TV - perpetuity growth | B48: =N37*(1+Assumptions!$C$49)*Assumptions!N36*(1-Assumptions!N$42)*(1-Assumptions!$C$49/Assumptions!$C$50)/(DCF!$B$14-Assumptions!$C$49)/(1+DCF!$B$14)^DCF!$B$27 -> 2108846.5
A49: Enterprise value - perpetuity growth | B49: =B47+B48 -> 4335206.9
...

Sheet ReverseDCF
A1: Reverse DCF - what is the market pricing in?
A2: Value per share (perpetuity-growth method) for a constant FY28-FY36 revenue CAGR and a given FY2036 operating margin. FY27E, WACC, g and RONIC from the live scenario; margin fades linearly from FY27E.
A3: Current share price | B3: =Assumptions!B9 -> 226.32
A4: Base-case FY28-36 revenue CAGR (live scenario) | B4: =(Forecast!N7/Forecast!E7)^(1/9)-1 -> 0.14411557
A5: Base-case FY2036E operating margin (live scenario) | B5: =Forecast!N8 -> 0.47
A6: Year index t (FY28 = 1 ... FY36 = 9) | F6: 1 | G6: 2 | H6: 3 | I6: 4 | J6: 5 | K6: 6 | L6: 7 | M6: 8 | N6: 9
A8: Revenue CAGR FY28-36 (down) vs FY2036 operating margin (across)
A9: CAGR / margin | B9: 0.35 | C9: 0.4 | D9: 0.45 | E9: 0.5 | F9: 0.55 | G9: 0.6 | H9: =Forecast!N8 -> 0.47
A10: 0.04 | B10: =(DCF!$E$7*DCF!$E$9+SUMPRODUCT((Forecast!$E$7*(1+$A10)^$F$6:$N$6*(Forecast!$E$8+(B$9-Forecast!$E$8)*$F$6:$N$6/9)*(1-Forecast!$F$13:$N$13)-(Forecast!$F$16:$N$16-Forecast!$F$10:$N$10)*Forecast!$E$7*(1+$A10)^$F$6:$N$6-Assumptions!$B$22*Forecast!$E$7*(1+$A10)^($F$6:$N$6-1)*$A10)/(1+DCF!$B$14)^(DCF!$B$15+$F$6:$N$6-0.5))+Forecast!$E$7*(1+$A10)^9*(1+DCF!$B$16)*B$9*(1-Forecast!$N$13)*(1-DCF!$B$16/DCF!$B$17)/(DCF!$B$14-DCF!$B$16)/(1+DCF!$B$14)^DCF!$B$27+DCF!$B$55)/Assumptions!$B$10 -> 76.394646 | C10: =(DCF!$E$7*DCF!$E$9+SUMPRODUCT((Forecast!$E$7*(1+$A10)^$F$6:$N$6*(Forecast!$E$8+(C$9-Forecast!$E$8)*$F$6:$N$6/9)*(1-Forecast!$F$13:$N$13)-(Forecast!$F$16:$N$16-Forecast!$F$10:$N$10)*Forecast!$E$7*(1+$A10)^$F$6:$N$6-Assumptions!$B$22*Forecast!$E$7*(1+$A10)^($F$6:$N$6-1)*$A10)/(1+DCF!$B$14)^(DCF!$B$15+$F$6:$N$6-0.5))+Forecast!$E$7*(1+$A10)^9*(1+DCF!$B$16)*C$9*(1-Forecast!$N$13)*(1-DCF!$B$16/DCF!$B$17)/(DCF!$B$14-DCF!$B$16)/(1+DCF!$B$14)^DCF!$B$27+DCF!$B$55)/Assumptions!$B$10 -> 82.516851 | D10: =(DCF!$E$7*DCF!$E$9+SUMPRODUCT((Forecast!$E$7*(1+$A10)^$F$6:$N$6*(Forecast!$E$8+(D$9-Forecast!$E$8)*$F$6:$N$6/9)*(1-Forecast!$F$13:$N$13)-(Forecast!$F$16:$N$16-Forecast!$F$10:$N$10)*Forecast!$E$7*(1+$A10)^$F$6:$N$6-Assumptions!$B$22*Forecast!$E$7*(1+$A10)^($F$6:$N$6-1)*$A10)/(1+DCF!$B$14)^(DCF!$B$15+$F$6:$N$6-0.5))+Forecast!$E$7*(1+$A10)^9*(1+DCF!$B$16)*D$9*(1-Forecast!$N$13)*(1-DCF!$B$16/DCF!$B$17)/(DCF!$B$14-DCF!$B$16)/(1+DCF!$B$14)^DCF!$B$27+DCF!$B$55)/Assumptions!$B$10 -> 88.639057 | E10: =(DCF!$E$7*DCF!$E$9+SUMPRODUCT((Forecast!$E$7*(1+$A10)^$F$6:$N$6*(Forecast!$E$8+(E$9-Forecast!$E$8)*$F$6:$N$6/9)*(1-Forecast!$F$13:$N$13)-(Forecast!$F$16:$N$16-Forecast!$F$10:$N$10)*Forecast!$E$7*(1+$A10)^$F$6:$N$6-Assumptions!$B$22*Forecast!$E$7*(1+$A10)^($F$6:$N$6-1)*$A10)/(1+DCF!$B$14)^(DCF!$B$15+$F$6:$N$6-0.5))+Forecast!$E$7*(1+$A10)^9*(1+DCF!$B$16)*E$9*(1-Forecast!$N$13)*(1-DCF!$B$16/DCF!$B$17)/(DCF!$B$14-DCF!$B$16)/(1+DCF!$B$14)^DCF!$B$27+DCF!$B$55)/Assumptions!$B$10 -> 94.761262 | F10: =(DCF!$E$7*DCF!$E$9+SUMPRODUCT((Forecast!$E$7*(1+$A10)^$F$6:$N$6*(Forecast!$E$8+(F$9-Forecast!$E$8)*$F$6:$N$6/9)*(1-Forecast!$F$13:$N$13)-(Forecast!$F$16:$N$16-Forecast!$F$10:$N$10)*Forecast!$E$7*(1+$A10)^$F$6:$N$6-Assumptions!$B$22*Forecast!$E$7*(1+$A10)^($F$6:$N$6-1)*$A10)/(1+DCF!$B$14)^(DCF!$B$15+$F$6:$N$6-0.5))+Forecast!$E$7*(1+$A10)^9*(1+DCF!$B$16)*F$9*(1-Forecast!$N$13)*(1-DCF!$B$16/DCF!$B$17)/(DCF!$B$14-DCF!$B$16)/(1+DCF!$B$14)^DCF!$B$27+DCF!$B$55)/Assumptions!$B$10 -> 100.88347 | G10: =(DCF!$E$7*DCF!$E$9+SUMPRODUCT((Forecast!$E$7*(1+$A10)^$F$6:$N$6*(Forecast!$E$8+(G$9-Forecast!$E$8)*$F$6:$N$6/9)*(1-Forecast!$F$13:$N$13)-(Forecast!$F$16:$N$16-Forecast!$F$10:$N$10)*Forecast!$E$7*(1+$A10)^$F$6:$N$6-Assumptions!$B$22*Forecast!$E$7*(1+$A10)^($F$6:$N$6-1)*$A10)/(1+DCF!$B$14)^(DCF!$B$15+$F$6:$N$6-0.5))+Forecast!$E$7*(1+$A10)^9*(1+DCF!$B$16)*G$9*(1-Forecast!$N$13)*(1-DCF!$B$16/DCF!$B$17)/(DCF!$B$14-DCF!$B$16)/(1+DCF!$B$14)^DCF!$B$27+DCF!$B$55)/Assumptions!$B$10 -> 107.00567 | H10: =(DCF!$E$7*DCF!$E$9+SUMPRODUCT((Forecast!$E$7*(1+$A10)^$F$6:$N$6*(Forecast!$E$8+(H$9-Forecast!$E$8)*$F$6:$N$6/9)*(1-Forecast!$F$13:$N$13)-(Forecast!$F$16:$N$16-Forecast!$F$10:$N$10)*Forecast!$E$7*(1+$A10)^$F$6:$N$6-Assumptions!$B$22*Forecast!$E$7*(1+$A10)^($F$6:$N$6-1)*$A10)/(1+DCF!$B$14)^(DCF!$B$15+$F$6:$N$6-0.5))+Forecast!$E$7*(1+$A10)^9*(1+DCF!$B$16)*H$9*(1-Forecast!$N$13)*(1-DCF!$B$16/DCF!$B$17)/(DCF!$B$14-DCF!$B$16)/(1+DCF!$B$14)^DCF!$B$27+DCF!$B$55)/Assumptions!$B$10 -> 91.087939
A11: 0.06 | B11: =(DCF!$E$7*DCF!$E$9+SUMPRODUCT((Forecast!$E$7*(1+$A11)^$F$6:$N$6*(Forecast!$E$8+(B$9-Forecast!$E$8)*$F$6:$N$6/9)*(1-Forecast!$F$13:$N$13)-(Forecast!$F$16:$N$16-Forecast!$F$10:$N$10)*Forecast!$E$7*(1+$A11)^$F$6:$N$6-Assumptions!$B$22*Forecast!$E$7*(1+$A11)^($F$6:$N$6-1)*$A11)/(1+DCF!$B$14)^(DCF!$B$15+$F$6:$N$6-0.5))+Forecast!$E$7*(1+$A11)^9*(1+DCF!$B$16)*B$9*(1-Forecast!$N$13)*(1-DCF!$B$16/DCF!$B$17)/(DCF!$B$14-DCF!$B$16)/(1+DCF!$B$14)^DCF!$B$27+DCF!$B$55)/Assumptions!$B$10 -> 84.679831 | C11: =(DCF!$E$7*DCF!$E$9+SUMPRODUCT((Forecast!$E$7*(1+$A11)^$F$6:$N$6*(Forecast!$E$8+(C$9-Forecast!$E$8)*$F$6:$N$6/9)*(1-Forecast!$F$13:$N$13)-(Forecast!$F$16:$N$16-Forecast!$F$10:$N$10)*Forecast!$E$7*(1+$A11)^$F$6:$N$6-Assumptions!$B$22*Forecast!$E$7*(1+$A11)^($F$6:$N$6-1)*$A11)/(1+DCF!$B$14)^(DCF!$B$15+$F$6:$N$6-0.5))+Forecast!$E$7*(1+$A11)^9*(1+DCF!$B$16)*C$9*(1-Forecast!$N$13)*(1-DCF!$B$16/DCF!$B$17)/(DCF!$B$14-DCF!$B$16)/(1+DCF!$B$14)^DCF!$B$27+DCF!$B$55)/Assumptions!$B$10 -> 91.801448 | D11: =(DCF!$E$7*DCF!$E$9+SUMPRODUCT((Forecast!$E$7*(1+$A11)^$F$6:$N$6*(Forecast!$E$8+(D$9-Forecast!$E$8)*$F$6:$N$6/9)*(1-Forecast!$F$13:$N$13)-(Forecast!$F$16:$N$16-Forecast!$F$10:$N$10)*Forecast!$E$7*(1+$A11)^$F$6:$N$6-Assumptions!$B$22*Forecast!$E$7*(1+$A11)^($F$6:$N$6-1)*$A11)/(1+DCF!$B$14)^(DCF!$B$15+$F$6:$N$6-0.5))+Forecast!$E$7*(1+$A11)^9*(1+DCF!$B$16)*D$9*(1-Forecast!$N$13)*(1-DCF!$B$16/DCF!$B$17)/(DCF!$B$14-DCF!$B$16)/(1+DCF!$B$14)^DCF!$B$27+DCF!$B$55)/Assumptions!$B$10 -> 98.923064 | E11: =(DCF!$E$7*DCF!$E$9+SUMPRODUCT((Forecast!$E$7*(1+$A11)^$F$6:$N$6*(Forecast!$E$8+(E$9-Forecast!$E$8)*$F$6:$N$6/9)*(1-Forecast!$F$13:$N$13)-(Forecast!$F$16:$N$16-Forecast!$F$10:$N$10)*Forecast!$E$7*(1+$A11)^$F$6:$N$6-Assumptions!$B$22*Forecast!$E$7*(1+$A11)^($F$6:$N$6-1)*$A11)/(1+DCF!$B$14)^(DCF!$B$15+$F$6:$N$6-0.5))+Forecast!$E$7*(1+$A11)^9*(1+DCF!$B$16)*E$9*(1-Forecast!$N$13)*(1-DCF!$B$16/DCF!$B$17)/(DCF!$B$14-DCF!$B$16)/(1+DCF!$B$14)^DCF!$B$27+DCF!$B$55)/Assumptions!$B$10 -> 106.04468 | F11: =(DCF!$E$7*DCF!$E$9+SUMPRODUCT((Forecast!$E$7*(1+$A11)^$F$6:$N$6*(Forecast!$E$8+(F$9-Forecast!$E$8)*$F$6:$N$6/9)*(1-Forecast!$F$13:$N$13)-(Forecast!$F$16:$N$16-Forecast!$F$10:$N$10)*Forecast!$E$7*(1+$A11)^$F$6:$N$6-Assumptions!$B$22*Forecast!$E$7*(1+$A11)^($F$6:$N$6-1)*$A11)/(1+DCF!$B$14)^(DCF!$B$15+$F$6:$N$6-0.5))+Forecast!$E$7*(1+$A11)^9*(1+DCF!$B$16)*F$9*(1-Forecast!$N$13)*(1-DCF!$B$16/DCF!$B$17)/(DCF!$B$14-DCF!$B$16)/(1+DCF!$B$14)^DCF!$B$27+DCF!$B$55)/Assumptions!$B$10 -> 113.1663 | G11: =(DCF!$E$7*DCF!$E$9+SUMPRODUCT((Forecast!$E$7*(1+$A11)^$F$6:$N$6*(Forecast!$E$8+(G$9-Forecast!$E$8)*$F$6:$N$6/9)*(1-Forecast!$F$13:$N$13)-(Forecast!$F$16:$N$16-Forecast!$F$10:$N$10)*Forecast!$E$7*(1+$A11)^$F$6:$N$6-Assumptions!$B$22*Forecast!$E$7*(1+$A11)^($F$6:$N$6-1)*$A11)/(1+DCF!$B$14)^(DCF!$B$15+$F$6:$N$6-0.5))+Forecast!$E$7*(1+$A11)^9*(1+DCF!$B$16)*G$9*(1-Forecast!$N$13)*(1-DCF!$B$16/DCF!$B$17)/(DCF!$B$14-DCF!$B$16)/(1+DCF!$B$14)^DCF!$B$27+DCF!$B$55)/Assumptions!$B$10 -> 120.28791 | H11: =(DCF!$E$7*DCF!$E$9+SUMPRODUCT((Forecast!$E$7*(1+$A11)^$F$6:$N$6*(Forecast!$E$8+(H$9-Forecast!$E$8)*$F$6:$N$6/9)*(1-Forecast!$F$13:$N$13)-(Forecast!$F$16:$N$16-Forecast!$F$10:$N$10)*Forecast!$E$7*(1+$A11)^$F$6:$N$6-Assumptions!$B$22*Forecast!$E$7*(1+$A11)^($F$6:$N$6-1)*$A11)/(1+DCF!$B$14)^(DCF!$B$15+$F$6:$N$6-0.5))+Forecast!$E$7*(1+$A11)^9*(1+DCF!$B$16)*H$9*(1-Forecast!$N$13)*(1-DCF!$B$16/DCF!$B$17)/(DCF!$B$14-DCF!$B$16)/(1+DCF!$B$14)^DCF!$B$27+DCF!$B$55)/Assumptions!$B$10 -> 101.77171
